Workbook
Name UPDATE: 'Data Sheet'!$E$1

Sheet Profit & Loss
A1: ='Data Sheet'!B1 -> NESTLE INDIA LTD | H1: =UPDATE | M1: SCREENER.IN
A3: Narration | B3: ='Data Sheet'!B16 -> 42735 | C3: ='Data Sheet'!C16 -> 43100 | D3: ='Data Sheet'!D16 -> 43465 | E3: ='Data Sheet'!E16 -> 43830 | F3: ='Data Sheet'!F16 -> 44196 | G3: ='Data Sheet'!G16 -> 44561 | H3: ='Data Sheet'!H16 -> 44926 | I3: ='Data Sheet'!I16 -> 45291 | ... K3: ='Data Sheet'!K16 -> 45747 | L3: Trailing | M3: Best Case | N3: Worst Case
A4: Sales | B4: ='Data Sheet'!B17 -> 9141.34 | C4: ='Data Sheet'!C17 -> 10009.6 | D4: ='Data Sheet'!D17 -> 11292.27 | E4: ='Data Sheet'!E17 -> 12368.9 | F4: ='Data Sheet'!F17 -> 13350.03 | G4: ='Data Sheet'!G17 -> 14740.59 | H4: ='Data Sheet'!H17 -> 16896.96 | I4: ='Data Sheet'!I17 -> 19126.3 | ... K4: ='Data Sheet'!K17 -> 20201.56 | L4: =SUM(Quarters!H4:K4) -> 21910.69 | M4: =$K4+M23*K4 -> 21910.69 | N4: =$K4+N23*L4 -> 21545.789
A5: Expenses | B5: =SUM('Data Sheet'!B18,'Data Sheet'!B20:B24, -1*'Data Sheet'!B19) -> 7291.5 | C5: =SUM('Data Sheet'!C18,'Data Sheet'!C20:C24, -1*'Data Sheet'!C19) -> 7913.07 | D5: =SUM('Data Sheet'!D18,'Data Sheet'!D20:D24, -1*'Data Sheet'!D19) -> 8674.62 | E5: =SUM('Data Sheet'!E18,'Data Sheet'!E20:E24, -1*'Data Sheet'!E19) -> 9443.02 | F5: =SUM('Data Sheet'!F18,'Data Sheet'!F20:F24, -1*'Data Sheet'!F19) -> 10148.53 | G5: =SUM('Data Sheet'!G18,'Data Sheet'!G20:G24, -1*'Data Sheet'!G19) -> 11178.19 | H5: =SUM('Data Sheet'!H18,'Data Sheet'!H20:H24, -1*'Data Sheet'!H19) -> 13190.67 | I5: =SUM('Data Sheet'!I18,'Data Sheet'!I20:I24, -1*'Data Sheet'!I19) -> 14655.31 | ... K5: =SUM('Data Sheet'!K18,'Data Sheet'!K20:K24, -1*'Data Sheet'!K19) -> 15430.23 | L5: =SUM(Quarters!H5:K5) -> 16982.76 | M5: =M4-M6 -> 16723.569 | N5: =N4-N6 -> 16699.929
A6: Operating Profit | B6: =B4-B5 -> 1849.84 | C6: =C4-C5 -> 2096.53 | D6: =D4-D5 -> 2617.65 | E6: =E4-E5 -> 2925.88 | F6: =F4-F5 -> 3201.5 | G6: =G4-G5 -> 3562.4 | H6: =H4-H5 -> 3706.29 | I6: =I4-I5 -> 4470.99 | ... K6: =K4-K5 -> 4771.33 | L6: =SUM(Quarters!H6:K6) -> 4927.93 | M6: =M4*M24 -> 5187.1206 | N6: =N4*N24 -> 4845.8602
A7: Other Income | B7: ='Data Sheet'!B25 -> 140.12 | C7: ='Data Sheet'!C25 -> 176.92 | D7: ='Data Sheet'!D25 -> 258.92 | E7: ='Data Sheet'!E25 -> 246.88 | F7: ='Data Sheet'!F25 -> 145.85 | G7: ='Data Sheet'!G25 -> -112.38 | H7: ='Data Sheet'!H25 -> 107.26 | I7: ='Data Sheet'!I25 -> 115.5 | ... K7: ='Data Sheet'!K25 -> 352.06 | L7: =SUM(Quarters!H7:K7) -> 182.78 | M7: 0 | N7: 0
A8: Depreciation | B8: ='Data Sheet'!B26 -> 353.67 | C8: ='Data Sheet'!C26 -> 342.25 | D8: ='Data Sheet'!D26 -> 335.67 | E8: ='Data Sheet'!E26 -> 370.15 | F8: ='Data Sheet'!F26 -> 370.38 | G8: ='Data Sheet'!G26 -> 391.02 | H8: ='Data Sheet'!H26 -> 403.01 | I8: ='Data Sheet'!I26 -> 428.91 | ... K8: ='Data Sheet'!K26 -> 539.92 | L8: =SUM(Quarters!H8:K8) -> 650.04 | M8: =+$L8 -> 650.04 | N8: =+$L8 -> 650.04
A9: Interest | B9: ='Data Sheet'!B27 -> 90.91 | C9: ='Data Sheet'!C27 -> 91.9 | D9: ='Data Sheet'!D27 -> 111.95 | E9: ='Data Sheet'!E27 -> 129.12 | F9: ='Data Sheet'!F27 -> 164.18 | G9: ='Data Sheet'!G27 -> 201.68 | H9: ='Data Sheet'!H27 -> 154.57 | I9: ='Data Sheet'!I27 -> 119.29 | ... K9: ='Data Sheet'!K27 -> 136 | L9: =SUM(Quarters!H9:K9) -> 159.05 | M9: =+$L9 -> 159.05 | N9: =+$L9 -> 159.05
A10: Profit before tax | B10: ='Data Sheet'!B28 -> 1545.38 | C10: ='Data Sheet'!C28 -> 1839.3 | D10: ='Data Sheet'!D28 -> 2428.95 | E10: ='Data Sheet'!E28 -> 2673.49 | F10: ='Data Sheet'!F28 -> 2812.79 | G10: ='Data Sheet'!G28 -> 2857.32 | H10: ='Data Sheet'!H28 -> 3255.97 | I10: ='Data Sheet'!I28 -> 4038.29 | ... K10: ='Data Sheet'!K28 -> 4447.47 | L10: =SUM(Quarters!H10:K10) -> 4301.62 | M10: =M6+M7-SUM(M8:M9) -> 4378.0306 | N10: =N6+N7-SUM(N8:N9) -> 4036.7702
A11: Tax | B11: ='Data Sheet'!B29 -> 544.02 | C11: ='Data Sheet'!C29 -> 614.11 | D11: ='Data Sheet'!D29 -> 822.02 | E11: ='Data Sheet'!E29 -> 705.05 | F11: ='Data Sheet'!F29 -> 730.36 | G11: ='Data Sheet'!G29 -> 738.91 | H11: ='Data Sheet'!H29 -> 865.45 | I11: ='Data Sheet'!I29 -> 1039.62 | ... K11: ='Data Sheet'!K29 -> 1132.97 | L11: =SUM(Quarters!H11:K11) -> 985.72 | M11: =IF($L10>0,$L11/$L10,0) -> 0.22915088 | N11: =IF($L10>0,$L11/$L10,0) -> 0.22915088
A12: Net profit | B12: ='Data Sheet'!B30 -> 1001.36 | C12: ='Data Sheet'!C30 -> 1225.19 | D12: ='Data Sheet'!D30 -> 1606.93 | E12: ='Data Sheet'!E30 -> 1968.44 | F12: ='Data Sheet'!F30 -> 2082.43 | G12: ='Data Sheet'!G30 -> 2118.41 | H12: ='Data Sheet'!H30 -> 2390.52 | I12: ='Data Sheet'!I30 -> 2998.67 | ... K12: ='Data Sheet'!K30 -> 3314.5 | L12: =SUM(Quarters!H12:K12) -> 3315.9 | M12: =M10-M11*M10 -> 3374.801 | N12: =N10-N11*N10 -> 3111.7407
A13: EPS | B13: =IF('Data Sheet'!B93>0,B12/'Data Sheet'!B93,0) -> 5.1937759 | C13: =IF('Data Sheet'!C93>0,C12/'Data Sheet'!C93,0) -> 6.3547199 | D13: =IF('Data Sheet'!D93>0,D12/'Data Sheet'!D93,0) -> 8.3346992 | E13: =IF('Data Sheet'!E93>0,E12/'Data Sheet'!E93,0) -> 10.209751 | F13: =IF('Data Sheet'!F93>0,F12/'Data Sheet'!F93,0) -> 10.800985 | G13: =IF('Data Sheet'!G93>0,G12/'Data Sheet'!G93,0) -> 10.987604 | H13: =IF('Data Sheet'!H93>0,H12/'Data Sheet'!H93,0) -> 12.398963 | I13: =IF('Data Sheet'!I93>0,I12/'Data Sheet'!I93,0) -> 15.553268 | ... K13: =IF('Data Sheet'!K93>0,K12/'Data Sheet'!K93,0) -> 17.188715 | L13: =IF('Data Sheet'!$B6>0,'Profit & Loss'!L12/'Data Sheet'!$B6,0) -> 17.195848 | M13: =IF('Data Sheet'!$B6>0,'Profit & Loss'!M12/'Data Sheet'!$B6,0) -> 17.501302 | N13: =IF('Data Sheet'!$B6>0,'Profit & Loss'!N12/'Data Sheet'!$B6,0) -> 16.137104
A14: Price to earning | B14: =IF(B15>0,B15/B13,"") -> 58.034849 | C14: =IF(C15>0,C15/C13,"") -> 61.930345 | D14: =IF(D15>0,D15/D13,"") -> 66.497901 | E14: =IF(E15>0,E15/E13,"") -> 72.40823 | F14: =IF(F15>0,F15/F13,"") -> 85.132047 | G14: =IF(G15>0,G15/G13,"") -> 89.672874 | H14: =IF(H15>0,H15/H13,"") -> 79.063066 | I14: =IF(I15>0,I15/I13,"") -> 85.449568 | ... K14: =IF(K15>0,K15/K13,"") -> 65.472025 | L14: =IF(L13>0,L15/L13,0) -> 73.235701 | M14: =M25 -> 73.235701 | N14: =N25 -> 72.11135
A15: Price | B15: ='Data Sheet'!B90 -> 301.42 | C15: ='Data Sheet'!C90 -> 393.55 | D15: ='Data Sheet'!D90 -> 554.24 | E15: ='Data Sheet'!E90 -> 739.27 | F15: ='Data Sheet'!F90 -> 919.51 | G15: ='Data Sheet'!G90 -> 985.29 | H15: ='Data Sheet'!H90 -> 980.3 | I15: ='Data Sheet'!I90 -> 1329.02 | ... K15: ='Data Sheet'!K90 -> 1125.38 | L15: ='Data Sheet'!B8 -> 1259.35 | M15: =M13*M14 -> 1281.7201 | N15: =N13*N14 -> 1163.6683
A17: RATIOS:
A18: Dividend Payout | B18: =IF('Data Sheet'!B30>0, 'Data Sheet'!B31/'Data Sheet'!B30, 0) -> 0.60662499 | C18: =IF('Data Sheet'!C30>0, 'Data Sheet'!C31/'Data Sheet'!C30, 0) -> 0.67680115 | D18: =IF('Data Sheet'!D30>0, 'Data Sheet'!D31/'Data Sheet'!D30, 0) -> 0.69003006 | E18: =IF('Data Sheet'!E30>0, 'Data Sheet'!E31/'Data Sheet'!E30, 0) -> 1.6752149 | F18: =IF('Data Sheet'!F30>0, 'Data Sheet'!F31/'Data Sheet'!F30, 0) -> 0.92603353 | G18: =IF('Data Sheet'!G30>0, 'Data Sheet'!G31/'Data Sheet'!G30, 0) -> 0.91030537 | H18: =IF('Data Sheet'!H30>0, 'Data Sheet'!H31/'Data Sheet'!H30, 0) -> 0.88735505 | I18: =IF('Data Sheet'!I30>0, 'Data Sheet'!I31/'Data Sheet'!I30, 0) -> 0.5594847 | ... K18: =IF('Data Sheet'!K30>0, 'Data Sheet'!K31/'Data Sheet'!K30, 0) -> 0.78543973
A19: OPM | B19: =IF(B6>0,B6/B4,0) -> 0.20235983 | C19: =IF(C6>0,C6/C4,0) -> 0.20945193 | D19: =IF(D6>0,D6/D4,0) -> 0.23180902 | E19: =IF(E6>0,E6/E4,0) -> 0.23655135 | F19: =IF(F6>0,F6/F4,0) -> 0.2398122 | G19: =IF(G6>0,G6/G4,0) -> 0.24167282 | H19: =IF(H6>0,H6/H4,0) -> 0.21934656 | I19: =IF(I6>0,I6/I4,0) -> 0.23376137 | ... L19: =IF(L6>0,L6/L4,0) -> 0.22490985
G22: TRENDS: | H22: 10 YEARS | I22: 7 YEARS | J22: 5 YEARS | K22: 3 YEARS | L22: RECENT | M22: BEST | N22: WORST
G23: Sales Growth | H23: =IF(B4=0,"",POWER($K4/B4,1/9)-1) -> 0.092103739 | I23: =IF(D4=0,"",POWER($K4/D4,1/7)-1) -> 0.086641373 | J23: =IF(F4=0,"",POWER($K4/F4,1/5)-1) -> 0.086376927 | K23: =IF(H4=0,"",POWER($K4/H4, 1/3)-1) -> 0.061350374 | L23: =IF(ISERROR(MAX(IF(J4=0,"",(K4-J4)/J4),IF(K4=0,"",(L4-K4)/K4))),"",MAX(IF(J4=0,"",(K4-J4)/J4),IF(K4=0,"",(L4-K4)/K4))) -> 0.084603862 | M23: =MAX(K23:L23) -> 0.084603862 | N23: =MIN(H23:L23) -> 0.061350374
G24: OPM | H24: =IF(SUM(B4:$K$4)=0,"",SUMPRODUCT(B19:$K$19,B4:$K$4)/SUM(B4:$K$4)) -> 0.2312909 | I24: =IF(SUM(E4:$K$4)=0,"",SUMPRODUCT(E19:$K$19,E4:$K$4)/SUM(E4:$K$4)) -> 0.2352323 | J24: =IF(SUM(G4:$K$4)=0,"",SUMPRODUCT(G19:$K$19,G4:$K$4)/SUM(G4:$K$4)) -> 0.23442003 | K24: =IF(SUM(I4:$K$4)=0, "", SUMPRODUCT(I19:$K$19,I4:$K$4)/SUM(I4:$K$4)) -> 0.23673926 | L24: =L19 -> 0.22490985 | M24: =MAX(K24:L24) -> 0.23673926 | N24: =MIN(H24:L24) -> 0.22490985
G25: Price to Earning | H25: =IF(ISERROR(AVERAGEIF(B14:$L14,">0")),"",AVERAGEIF(B14:$L14,">0")) -> 72.834974 | I25: =IF(ISERROR(AVERAGEIF(E14:$L14,">0")),"",AVERAGEIF(E14:$L14,">0")) -> 76.840202 | J25: =IF(ISERROR(AVERAGEIF(G14:$L14,">0")),"",AVERAGEIF(G14:$L14,">0")) -> 76.19689 | K25: =IF(ISERROR(AVERAGEIF(I14:$L14,">0")),"",AVERAGEIF(I14:$L14,">0")) -> 72.11135 | L25: =L14 -> 73.235701 | M25: =MAX(K25:L25) -> 73.235701 | N25: =MIN(H25:L25) -> 72.11135

Sheet Quarters
A1: ='Profit & Loss'!A1 -> NESTLE INDIA LTD | E1: =UPDATE | J1: SCREENER.IN
A3: Narration | B3: ='Data Sheet'!B41 -> 45199 | C3: ='Data Sheet'!C41 -> 45291 | D3: ='Data Sheet'!D41 -> 45382 | E3: ='Data Sheet'!E41 -> 45473 | F3: ='Data Sheet'!F41 -> 45565 | G3: ='Data Sheet'!G41 -> 45657 | H3: ='Data Sheet'!H41 -> 45747 | I3: ='Data Sheet'!I41 -> 45838 | ... K3: ='Data Sheet'!K41 -> 46022
A4: Sales | B4: ='Data Sheet'!B42 -> 5036.82 | C4: ='Data Sheet'!C42 -> 4600.42 | D4: ='Data Sheet'!D42 -> 5267.59 | E4: ='Data Sheet'!E42 -> 4813.95 | F4: ='Data Sheet'!F42 -> 5104 | G4: ='Data Sheet'!G42 -> 4779.73 | H4: ='Data Sheet'!H42 -> 5503.88 | I4: ='Data Sheet'!I42 -> 5096.16 | ... K4: ='Data Sheet'!K42 -> 5667.04
A5: Expenses | B5: ='Data Sheet'!B43 -> 3811.95 | C5: ='Data Sheet'!C43 -> 3505.3 | D5: ='Data Sheet'!D43 -> 3917.54 | E5: ='Data Sheet'!E43 -> 3699.62 | F5: ='Data Sheet'!F43 -> 3936.27 | G5: ='Data Sheet'!G43 -> 3677.04 | H5: ='Data Sheet'!H43 -> 4114.92 | I5: ='Data Sheet'!I43 -> 3995.9 | ... K5: ='Data Sheet'!K43 -> 4464.97
A6: Operating Profit | B6: ='Data Sheet'!B50 -> 1224.87 | C6: ='Data Sheet'!C50 -> 1095.12 | D6: ='Data Sheet'!D50 -> 1350.05 | E6: ='Data Sheet'!E50 -> 1114.33 | F6: ='Data Sheet'!F50 -> 1167.73 | G6: ='Data Sheet'!G50 -> 1102.69 | H6: ='Data Sheet'!H50 -> 1388.96 | I6: ='Data Sheet'!I50 -> 1100.26 | ... K6: ='Data Sheet'!K50 -> 1202.07
A7: Other Income | B7: ='Data Sheet'!B44 -> 139.69 | C7: ='Data Sheet'!C44 -> -77 | D7: ='Data Sheet'!D44 -> 36.83 | E7: ='Data Sheet'!E44 -> 39.12 | F7: ='Data Sheet'!F44 -> 297.68 | G7: ='Data Sheet'!G44 -> 4.44 | H7: ='Data Sheet'!H44 -> 8.44 | I7: ='Data Sheet'!I44 -> 4.04 | ... K7: ='Data Sheet'!K44 -> 168.66
A8: Depreciation | B8: ='Data Sheet'!B45 -> 111.16 | C8: ='Data Sheet'!C45 -> 108.69 | D8: ='Data Sheet'!D45 -> 110.1 | E8: ='Data Sheet'!E45 -> 112.71 | F8: ='Data Sheet'!F45 -> 121.6 | G8: ='Data Sheet'!G45 -> 150.27 | H8: ='Data Sheet'!H45 -> 155.34 | I8: ='Data Sheet'!I45 -> 156.94 | ... K8: ='Data Sheet'!K45 -> 174.41
A9: Interest | B9: ='Data Sheet'!B46 -> 31.38 | C9: ='Data Sheet'!C46 -> 22.95 | D9: ='Data Sheet'!D46 -> 26.2 | E9: ='Data Sheet'!E46 -> 31.68 | F9: ='Data Sheet'!F46 -> 32.22 | G9: ='Data Sheet'!G46 -> 34.6 | H9: ='Data Sheet'!H46 -> 37.5 | I9: ='Data Sheet'!I46 -> 46.89 | ... K9: ='Data Sheet'!K46 -> 28.25
A10: Profit before tax | B10: ='Data Sheet'!B47 -> 1222.02 | C10: ='Data Sheet'!C47 -> 886.48 | D10: ='Data Sheet'!D47 -> 1250.58 | E10: ='Data Sheet'!E47 -> 1009.06 | F10: ='Data Sheet'!F47 -> 1311.59 | G10: ='Data Sheet'!G47 -> 922.26 | H10: ='Data Sheet'!H47 -> 1204.56 | I10: ='Data Sheet'!I47 -> 900.47 | ... K10: ='Data Sheet'!K47 -> 1168.07
A11: Tax | B11: ='Data Sheet'!B48 -> 313.94 | C11: ='Data Sheet'!C48 -> 230.87 | D11: ='Data Sheet'!D48 -> 316.41 | E11: ='Data Sheet'!E48 -> 262.46 | F11: ='Data Sheet'!F48 -> 325.23 | G11: ='Data Sheet'!G48 -> 226.13 | H11: ='Data Sheet'!H48 -> 319.15 | I11: ='Data Sheet'!I48 -> 241.24 | ... K11: ='Data Sheet'!K48 -> 150.01
A12: Net profit | B12: ='Data Sheet'!B49 -> 908.08 | C12: ='Data Sheet'!C49 -> 655.61 | D12: ='Data Sheet'!D49 -> 934.17 | E12: ='Data Sheet'!E49 -> 746.6 | F12: ='Data Sheet'!F49 -> 986.36 | G12: ='Data Sheet'!G49 -> 696.13 | H12: ='Data Sheet'!H49 -> 885.41 | I12: ='Data Sheet'!I49 -> 659.23 | ... K12: ='Data Sheet'!K49 -> 1018.06
A14: OPM | B14: =IF(B4>0,B6/B4,"") -> 0.2431832 | C14: =IF(C4>0,C6/C4,"") -> 0.23804783 | D14: =IF(D4>0,D6/D4,"") -> 0.25629368 | E14: =IF(E4>0,E6/E4,"") -> 0.23147935 | F14: =IF(F4>0,F6/F4,"") -> 0.22878723 | G14: =IF(G4>0,G6/G4,"") -> 0.23070132 | H14: =IF(H4>0,H6/H4,"") -> 0.25236015 | I14: =IF(I4>0,I6/I4,"") -> 0.21589981 | ... K14: =IF(K4>0,K6/K4,"") -> 0.21211603

Sheet Balance Sheet
A1: ='Profit & Loss'!A1 -> NESTLE INDIA LTD | E1: =UPDATE | J1: SCREENER.IN
A3: Narration | B3: ='Data Sheet'!B56 -> 42735 | C3: ='Data Sheet'!C56 -> 43100 | D3: ='Data Sheet'!D56 -> 43465 | E3: ='Data Sheet'!E56 -> 43830 | F3: ='Data Sheet'!F56 -> 44196 | G3: ='Data Sheet'!G56 -> 44561 | H3: ='Data Sheet'!H56 -> 44926 | I3: ='Data Sheet'!I56 -> 45291 | ... K3: ='Data Sheet'!K56 -> 45747
A4: Equity Share Capital | B4: ='Data Sheet'!B57 -> 96.42 | C4: ='Data Sheet'!C57 -> 96.42 | D4: ='Data Sheet'!D57 -> 96.42 | E4: ='Data Sheet'!E57 -> 96.42 | F4: ='Data Sheet'!F57 -> 96.42 | G4: ='Data Sheet'!G57 -> 96.42 | H4: ='Data Sheet'!H57 -> 96.42 | I4: ='Data Sheet'!I57 -> 96.42 | ... K4: ='Data Sheet'!K57 -> 96.42
A5: Reserves | B5: ='Data Sheet'!B58 -> 3185.91 | C5: ='Data Sheet'!C58 -> 3324.17 | D5: ='Data Sheet'!D58 -> 3577.32 | E5: ='Data Sheet'!E58 -> 1822.45 | F5: ='Data Sheet'!F58 -> 1922.92 | G5: ='Data Sheet'!G58 -> 1849.96 | H5: ='Data Sheet'!H58 -> 2362.75 | I5: ='Data Sheet'!I58 -> 2362.75 | ... K5: ='Data Sheet'!K58 -> 4020.73
A6: Borrowings | B6: ='Data Sheet'!B59 -> 33.15 | C6: ='Data Sheet'!C59 -> 35.14 | D6: ='Data Sheet'!D59 -> 35.14 | E6: ='Data Sheet'!E59 -> 188.94 | F6: ='Data Sheet'!F59 -> 147.49 | G6: ='Data Sheet'!G59 -> 266.46 | H6: ='Data Sheet'!H59 -> 270.52 | I6: ='Data Sheet'!I59 -> 270.52 | ... K6: ='Data Sheet'!K59 -> 1166.85
A7: Other Liabilities | B7: ='Data Sheet'!B60 -> 3494.98 | C7: ='Data Sheet'!C60 -> 3906.86 | D7: ='Data Sheet'!D60 -> 4379.2 | E7: ='Data Sheet'!E60 -> 5065.13 | F7: ='Data Sheet'!F60 -> 5732.9 | G7: ='Data Sheet'!G60 -> 6021.29 | H7: ='Data Sheet'!H60 -> 6249.05 | I7: ='Data Sheet'!I60 -> 6249.05 | ... K7: ='Data Sheet'!K60 -> 7039.89
A8: Total | B8: ='Data Sheet'!B61 -> 6810.46 | C8: ='Data Sheet'!C61 -> 7362.59 | D8: ='Data Sheet'!D61 -> 8088.08 | E8: ='Data Sheet'!E61 -> 7172.94 | F8: ='Data Sheet'!F61 -> 7899.73 | G8: ='Data Sheet'!G61 -> 8234.13 | H8: ='Data Sheet'!H61 -> 8978.74 | I8: ='Data Sheet'!I61 -> 8978.74 | ... K8: ='Data Sheet'!K61 -> 12323.89
A10: Net Block | B10: ='Data Sheet'!B62 -> 2730.14 | C10: ='Data Sheet'!C62 -> 2616.18 | D10: ='Data Sheet'!D62 -> 2400.62 | E10: ='Data Sheet'!E62 -> 2341.45 | F10: ='Data Sheet'!F62 -> 2179.41 | G10: ='Data Sheet'!G62 -> 2994.67 | H10: ='Data Sheet'!H62 -> 3043.7 | I10: ='Data Sheet'!I62 -> 3043.7 | ... K10: ='Data Sheet'!K62 -> 5473.61
A11: Capital Work in Progress | B11: ='Data Sheet'!B63 -> 188.17 | C11: ='Data Sheet'!C63 -> 94.16 | D11: ='Data Sheet'!D63 -> 105.2 | E11: ='Data Sheet'!E63 -> 143.3 | F11: ='Data Sheet'!F63 -> 638.58 | G11: ='Data Sheet'!G63 -> 246.23 | H11: ='Data Sheet'!H63 -> 358.36 | I11: ='Data Sheet'!I63 -> 358.36 | ... K11: ='Data Sheet'!K63 -> 1172.56
A12: Investments | B12: ='Data Sheet'!B64 -> 1755.66 | C12: ='Data Sheet'!C64 -> 1978.87 | D12: ='Data Sheet'!D64 -> 2658.49 | E12: ='Data Sheet'!E64 -> 1751.05 | F12: ='Data Sheet'!F64 -> 1463.77 | G12: ='Data Sheet'!G64 -> 773.98 | H12: ='Data Sheet'!H64 -> 777.54 | I12: ='Data Sheet'!I64 -> 777.54 | ... K12: ='Data Sheet'!K64 -> 705.6
A13: Other Assets | B13: ='Data Sheet'!B65 -> 2136.49 | C13: ='Data Sheet'!C65 -> 2673.38 | D13: ='Data Sheet'!D65 -> 2923.77 | E13: ='Data Sheet'!E65 -> 2937.14 | F13: ='Data Sheet'!F65 -> 3617.97 | G13: ='Data Sheet'!G65 -> 4219.25 | H13: ='Data Sheet'!H65 -> 4799.14 | I13: ='Data Sheet'!I65 -> 4799.14 | ... K13: ='Data Sheet'!K65 -> 4972.12
A14: Total | B14: ='Data Sheet'!B66 -> 6810.46 | C14: ='Data Sheet'!C66 -> 7362.59 | D14: ='Data Sheet'!D66 -> 8088.08 | E14: ='Data Sheet'!E66 -> 7172.94 | F14: ='Data Sheet'!F66 -> 7899.73 | G14: ='Data Sheet'!G66 -> 8234.13 | H14: ='Data Sheet'!H66 -> 8978.74 | I14: ='Data Sheet'!I66 -> 8978.74 | ... K14: ='Data Sheet'!K66 -> 12323.89
A16: Working Capital | B16: =B13-B7 -> -1358.49 | C16: =C13-C7 -> -1233.48 | D16: =D13-D7 -> -1455.43 | E16: =E13-E7 -> -2127.99 | F16: =F13-F7 -> -2114.93 | G16: =G13-G7 -> -1802.04 | H16: =H13-H7 -> -1449.91 | I16: =I13-I7 -> -1449.91 | ... K16: =K13-K7 -> -2067.77
A17: Debtors | B17: ='Data Sheet'!B67 -> 97.93 | C17: ='Data Sheet'!C67 -> 88.97 | D17: ='Data Sheet'!D67 -> 124.59 | E17: ='Data Sheet'!E67 -> 124.33 | F17: ='Data Sheet'!F67 -> 164.93 | G17: ='Data Sheet'!G67 -> 165.97 | H17: ='Data Sheet'!H67 -> 191.89 | I17: ='Data Sheet'!I67 -> 191.89 | ... K17: ='Data Sheet'!K67 -> 363.15
A18: Inventory | B18: ='Data Sheet'!B68 -> 940.06 | C18: ='Data Sheet'!C68 -> 902.47 | D18: ='Data Sheet'!D68 -> 965.55 | E18: ='Data Sheet'!E68 -> 1283.07 | F18: ='Data Sheet'!F68 -> 1416.48 | G18: ='Data Sheet'!G68 -> 1592.65 | H18: ='Data Sheet'!H68 -> 1928.77 | I18: ='Data Sheet'!I68 -> 1928.77 | ... K18: ='Data Sheet'!K68 -> 2850.14
A20: Debtor Days | B20: =IF('Profit & Loss'!B4>0,'Balance Sheet'!B17/('Profit & Loss'!B4/365),0) -> 3.9101981 | C20: =IF('Profit & Loss'!C4>0,'Balance Sheet'!C17/('Profit & Loss'!C4/365),0) -> 3.2442905 | D20: =IF('Profit & Loss'!D4>0,'Balance Sheet'!D17/('Profit & Loss'!D4/365),0) -> 4.0271221 | E20: =IF('Profit & Loss'!E4>0,'Balance Sheet'!E17/('Profit & Loss'!E4/365),0) -> 3.6689156 | F20: =IF('Profit & Loss'!F4>0,'Balance Sheet'!F17/('Profit & Loss'!F4/365),0) -> 4.509312 | G20: =IF('Profit & Loss'!G4>0,'Balance Sheet'!G17/('Profit & Loss'!G4/365),0) -> 4.1096761 | H20: =IF('Profit & Loss'!H4>0,'Balance Sheet'!H17/('Profit & Loss'!H4/365),0) -> 4.1451155 | I20: =IF('Profit & Loss'!I4>0,'Balance Sheet'!I17/('Profit & Loss'!I4/365),0) -> 3.6619655 | ... K20: =IF('Profit & Loss'!K4>0,'Balance Sheet'!K17/('Profit & Loss'!K4/365),0) -> 6.5613621
A21: Inventory Turnover | B21: =IF('Balance Sheet'!B18>0,'Profit & Loss'!B4/'Balance Sheet'!B18,0) -> 9.7242091 | C21: =IF('Balance Sheet'!C18>0,'Profit & Loss'!C4/'Balance Sheet'!C18,0) -> 11.091338 | D21: =IF('Balance Sheet'!D18>0,'Profit & Loss'!D4/'Balance Sheet'!D18,0) -> 11.695169 | E21: =IF('Balance Sheet'!E18>0,'Profit & Loss'!E4/'Balance Sheet'!E18,0) -> 9.640082 | F21: =IF('Balance Sheet'!F18>0,'Profit & Loss'!F4/'Balance Sheet'!F18,0) -> 9.4247924 | G21: =IF('Balance Sheet'!G18>0,'Profit & Loss'!G4/'Balance Sheet'!G18,0) -> 9.2553857 | H21: =IF('Balance Sheet'!H18>0,'Profit & Loss'!H4/'Balance Sheet'!H18,0) -> 8.7604847 | I21: =IF('Balance Sheet'!I18>0,'Profit & Loss'!I4/'Balance Sheet'!I18,0) -> 9.9163197 | ... K21: =IF('Balance Sheet'!K18>0,'Profit & Loss'!K4/'Balance Sheet'!K18,0) -> 7.0879185
A23: Return on Equity | B23: =IF(SUM('Balance Sheet'!B4:B5)>0,'Profit & Loss'!B12/SUM('Balance Sheet'!B4:B5),"") -> 0.30507597 | C23: =IF(SUM('Balance Sheet'!C4:C5)>0,'Profit & Loss'!C12/SUM('Balance Sheet'!C4:C5),"") -> 0.3581809 | D23: =IF(SUM('Balance Sheet'!D4:D5)>0,'Profit & Loss'!D12/SUM('Balance Sheet'!D4:D5),"") -> 0.43740983 | E23: =IF(SUM('Balance Sheet'!E4:E5)>0,'Profit & Loss'!E12/SUM('Balance Sheet'!E4:E5),"") -> 1.0258329 | F23: =IF(SUM('Balance Sheet'!F4:F5)>0,'Profit & Loss'!F12/SUM('Balance Sheet'!F4:F5),"") -> 1.0312429 | G23: =IF(SUM('Balance Sheet'!G4:G5)>0,'Profit & Loss'!G12/SUM('Balance Sheet'!G4:G5),"") -> 1.0883846 | H23: =IF(SUM('Balance Sheet'!H4:H5)>0,'Profit & Loss'!H12/SUM('Balance Sheet'!H4:H5),"") -> 0.97208408 | I23: =IF(SUM('Balance Sheet'!I4:I5)>0,'Profit & Loss'!I12/SUM('Balance Sheet'!I4:I5),"") -> 1.219383 | ... K23: =IF(SUM('Balance Sheet'!K4:K5)>0,'Profit & Loss'!K12/SUM('Balance Sheet'!K4:K5),"") -> 0.80504718
A24: Return on Capital Emp | C24: =IF((B4+B5+B6+C4+C5+C6)>0,('Profit & Loss'!C10+'Profit & Loss'!C9)*2/(B4+B5+B6+C4+C5+C6),"") -> 0.57041504 | D24: =IF((C4+C5+C6+D4+D5+D6)>0,('Profit & Loss'!D10+'Profit & Loss'!D9)*2/(C4+C5+C6+D4+D5+D6),"") -> 0.70929192 | E24: =IF((D4+D5+D6+E4+E5+E6)>0,('Profit & Loss'!E10+'Profit & Loss'!E9)*2/(D4+D5+D6+E4+E5+E6),"") -> 0.96364427 | F24: =IF((E4+E5+E6+F4+F5+F6)>0,('Profit & Loss'!F10+'Profit & Loss'!F9)*2/(E4+E5+E6+F4+F5+F6),"") -> 1.3928518 | G24: =IF((F4+F5+F6+G4+G5+G6)>0,('Profit & Loss'!G10+'Profit & Loss'!G9)*2/(F4+F5+F6+G4+G5+G6),"") -> 1.3969089 | H24: =IF((G4+G5+G6+H4+H5+H6)>0,('Profit & Loss'!H10+'Profit & Loss'!H9)*2/(G4+G5+G6+H4+H5+H6),"") -> 1.3800786 | I24: =IF((H4+H5+H6+I4+I5+I6)>0,('Profit & Loss'!I10+'Profit & Loss'!I9)*2/(H4+H5+H6+I4+I5+I6),"") -> 1.523096 | J24: =IF((I4+I5+I6+J4+J5+J6)>0,('Profit & Loss'!J10+'Profit & Loss'!J9)*2/(I4+I5+I6+J4+J5+J6),"") -> 1.6942375 | K24: =IF((J4+J5+J6+K4+K5+K6)>0,('Profit & Loss'!K10+'Profit & Loss'!K9)*2/(J4+J5+J6+K4+K5+K6),"") -> 1.0220215

Sheet Cash Flow
A1: ='Balance Sheet'!A1 -> NESTLE INDIA LTD | E1: =UPDATE | J1: SCREENER.IN
A3: Narration | B3: ='Data Sheet'!B81 -> 42735 | C3: ='Data Sheet'!C81 -> 43100 | D3: ='Data Sheet'!D81 -> 43465 | E3: ='Data Sheet'!E81 -> 43830 | F3: ='Data Sheet'!F81 -> 44196 | G3: ='Data Sheet'!G81 -> 44561 | H3: ='Data Sheet'!H81 -> 44926 | I3: ='Data Sheet'!I81 -> 45291 | ... K3: ='Data Sheet'!K81 -> 45747
A4: Cash from Operating Activity | B4: ='Data Sheet'!B82 -> 1465.91 | C4: ='Data Sheet'!C82 -> 1817.79 | D4: ='Data Sheet'!D82 -> 2052.45 | E4: ='Data Sheet'!E82 -> 2295.25 | F4: ='Data Sheet'!F82 -> 2454.48 | G4: ='Data Sheet'!G82 -> 2236 | H4: ='Data Sheet'!H82 -> 2737.43 | I4: ='Data Sheet'!I82 -> 3392.19 | ... K4: ='Data Sheet'!K82 -> 2936.35
A5: Cash from Investing Activity | B5: ='Data Sheet'!B83 -> -125.9 | C5: ='Data Sheet'!C83 -> -130.56 | D5: ='Data Sheet'!D83 -> -52.41 | E5: ='Data Sheet'!E83 -> 82.99 | F5: ='Data Sheet'!F83 -> -321.46 | G5: ='Data Sheet'!G83 -> -1920.33 | H5: ='Data Sheet'!H83 -> -391.73 | I5: ='Data Sheet'!I83 -> -926.99 | ... K5: ='Data Sheet'!K83 -> -1810.9
A6: Cash from Financing Activity | B6: ='Data Sheet'!B84 -> -665.61 | C6: ='Data Sheet'!C84 -> -996.62 | D6: ='Data Sheet'!D84 -> -1317.42 | E6: ='Data Sheet'!E84 -> -3601.53 | F6: ='Data Sheet'!F84 -> -1955.89 | G6: ='Data Sheet'!G84 -> -2019.97 | H6: ='Data Sheet'!H84 -> -2122.74 | I6: ='Data Sheet'!I84 -> -2436.47 | ... K6: ='Data Sheet'!K84 -> -1848.12
A7: Net Cash Flow | B7: ='Data Sheet'!B85 -> 674.4 | C7: ='Data Sheet'!C85 -> 690.61 | D7: ='Data Sheet'!D85 -> 682.62 | E7: ='Data Sheet'!E85 -> -1223.29 | F7: ='Data Sheet'!F85 -> 177.13 | G7: ='Data Sheet'!G85 -> -1704.3 | H7: ='Data Sheet'!H85 -> 222.96 | I7: ='Data Sheet'!I85 -> 28.73 | ... K7: ='Data Sheet'!K85 -> -722.67

Sheet Customization
A1: How to use it?
A3: You can customize this workbook as you want.
B4: You can add custom formating, add conditional formating, add your own formulas… do ANYTHING.
B5: Please don't edit the "Data Sheet" only.
A7: After customization, you can upload this back on Screener.
B8: Upload on: | C8: https://www.screener.in/excel/
A10: Download your customized workbooks now onwards.
B11: Now whenever you will "Export to excel" from Screener, it will export your customized file.
A14: TESTING:
B15: This is a testing feature currently.
B16: You can report any formula errors on the worksheet at: support@screener.in

Sheet cash flows
A2: Cash Flows
A3: Standalone Figures in Rs. Crores / View Consolidated
B4: 41974 | C4: 42339 | D4: 42705 | E4: 43070 | F4: 43435 | G4: 43800 | H4: 44166 | I4: 44531 | J4: 44896 | K4: 45261 | L4: 45352 | M4: 45717
A5: Cash from Operating Activity - | B5: 1644 | C5: 1098 | D5: 1466 | E5: 1818 | F5: 2052 | G5: 2295 | H5: 2454 | I5: 2236 | J5: 2737 | K5: 3392 | L5: 4175 | M5: 2936
A6: Profit from operations | B6: 2051 | C6: 1109 | D6: 1765 | E6: 2047 | F6: 2521 | G6: 2805 | H6: 3061 | I6: 3136 | J6: 3609 | K6: 4388 | L6: 5722 | M6: 4672
A7: Receivables | B7: -14 | C7: 21 | D7: -19 | E7: 8 | F7: -36 | G7: 0 | H7: -42 | I7: -2 | J7: -28 | K7: -11 | L7: -109 | M7: -70
A8: Inventory | B8: -108 | C8: 23 | D8: -119 | E8: 38 | F8: -63 | G8: -318 | H8: -133 | I8: -169 | J8: -336 | K8: 56 | L8: -161 | M8: -767
A9: Payables | B9: 118 | C9: 79 | D9: 50 | E9: 185 | F9: 257 | G9: 253 | H9: 23 | I9: 217 | J9: 178 | K9: 68 | L9: 310 | M9: 134
A10: Loans Advances | B10: 34 | C10: -3 | D10: 0 | E10: 0 | F10: 0 | G10: 0 | H10: 0 | I10: -40 | J10: -30 | K10: -30 | L10: -21 | M10: -199
A11: Operating borrowings | B11: 0 | C11: 2 | D11: 0 | E11: 0 | F11: 0 | G11: 0 | H11: 0 | I11: 0 | J11: 0 | K11: 0 | L11: 0 | M11: 0
A12: Other WC items | B12: 153 | C12: 210 | D12: 293 | E12: 144 | F12: 255 | G12: 227 | H12: 249 | I12: -179 | J12: 185 | K12: -19 | L12: -268 | M12: 191
A13: Working capital changes | B13: 182 | C13: 332 | D13: 204 | E13: 375 | F13: 413 | G13: 163 | H13: 97 | I13: -172 | J13: -30 | K13: 63 | L13: -249 | M13: -711
A14: Direct taxes | B14: -589 | C14: -342 | D14: -503 | E14: -604 | F14: -881 | G14: -673 | H14: -703 | I14: -729 | J14: -841 | K14: -1059 | L14: -1299 | M14: -1024
A15: Cash from Investing Activity - | B15: -432 | C15: -70 | D15: -126 | E15: -131 | F15: -52 | G15: 83 | H15: -321 | I15: -1920 | J15: -392 | K15: -927 | L15: -1237 | M15: -1811
A16: Fixed assets purchased | B16: -415 | C16: -151 | D16: -207 | E16: -199 | F16: -166 | G16: -155 | H16: -478 | I16: -735 | J16: -550 | K16: -1371 | L16: -1883 | M16: -2009
... A34: CFO/OP | B34: 1.1 | C34: 0.93 | D34: 1.06 | E34: 1.16 | F34: 1.12 | G34: 1.01 | H34: 0.99 | I34: 0.83 | J34: 0.97 | K34: 1 | L34: 0.94 | M34: 0.83

Sheet Data Sheet
A1: COMPANY NAME | B1: NESTLE INDIA LTD | E1: =IF(B2<>B3, "A NEW VERSION OF THE WORKSHEET IS AVAILABLE", "")
A2: LATEST VERSION | B2: 2.1 | E2: PLEASE DO NOT MAKE ANY CHANGES TO THIS SHEET
A3: CURRENT VERSION | B3: 2.1
A5: META
A6: Number of shares | B6: =IF(B9>0, B9/B8, 0) -> 192.83143
A7: Face Value | B7: 1
A8: Current Price | B8: 1259.35
A9: Market Capitalization | B9: 242842.26
A15: PROFIT & LOSS
A16: Report Date | B16: 42735 | C16: 43100 | D16: 43465 | E16: 43830 | F16: 44196 | G16: 44561 | H16: 44926 | I16: 45291 | J16: 45382 | K16: 45747
A17: Sales | B17: 9141.34 | C17: 10009.6 | D17: 11292.27 | E17: 12368.9 | F17: 13350.03 | G17: 14740.59 | H17: 16896.96 | I17: 19126.3 | J17: 24393.89 | K17: 20201.56
A18: Raw Material Cost | B18: 3227.26 | C18: 3696.99 | D18: 3829.22 | E18: 4520.91 | F18: 4901.74 | G18: 5301.26 | H18: 6660.42 | I18: 8472.72 | J18: 9201.11 | K18: 7646.63
A19: Change in Inventory | B19: 7.66 | C19: 79.56 | D19: 6.01 | E19: 144.19 | F19: 69.33 | G19: 67.59 | H19: 250.27 | I19: 40.01 | J19: 45.68 | K19: 139.66
A20: Power and Fuel | B20: 232.79 | C20: 288.44 | D20: 344.18 | E20: 340.53 | F20: 313.68 | G20: 408.06 | H20: 572.61 | J20: 674.83 | K20: 536.65
A21: Other Mfr. Exp | B21: 850.85 | C21: 897.84 | D21: 949.86 | E21: 1028.55 | F21: 1040.36 | G21: 1349.48 | H21: 1603.48 | J21: 1935.4 | K21: 1579.8
A22: Employee Cost | B22: 901.57 | C22: 1017.45 | D22: 1124.15 | E22: 1258.17 | F22: 1500.95 | G22: 1529.94 | H22: 1635.46 | I22: 1849.18 | J22: 2336.06 | K22: 2023.71
A23: Selling and admin | B23: 1751.78 | C23: 1823.98 | D23: 2145.82 | E23: 2226.13 | F23: 2246.9 | G23: 2902.12 | H23: 3192.15 | J23: 4837.58 | K23: 4121.66
A24: Other Expenses | B24: 334.91 | C24: 267.93 | D24: 287.4 | E24: 212.92 | F24: 214.23 | G24: -245.08 | H24: -223.18 | I24: 4373.42 | J24: -388.53 | K24: -338.56
A25: Other Income | B25: 140.12 | C25: 176.92 | D25: 258.92 | E25: 246.88 | F25: 145.85 | G25: -112.38 | H25: 107.26 | I25: 115.5 | J25: 158.99 | K25: 352.06
A26: Depreciation | B26: 353.67 | C26: 342.25 | D26: 335.67 | E26: 370.15 | F26: 370.38 | G26: 391.02 | H26: 403.01 | I26: 428.91 | J26: 567.75 | K26: 539.92
A27: Interest | B27: 90.91 | C27: 91.9 | D27: 111.95 | E27: 129.12 | F27: 164.18 | G27: 201.68 | H27: 154.57 | I27: 119.29 | J27: 145.49 | K27: 136
A28: Profit before tax | B28: 1545.38 | C28: 1839.3 | D28: 2428.95 | E28: 2673.49 | F28: 2812.79 | G28: 2857.32 | H28: 3255.97 | I28: 4038.29 | J28: 5288.87 | K28: 4447.47
A29: Tax | B29: 544.02 | C29: 614.11 | D29: 822.02 | E29: 705.05 | F29: 730.36 | G29: 738.91 | H29: 865.45 | I29: 1039.62 | J29: 1356.03 | K29: 1132.97
A30: Net profit | B30: 1001.36 | C30: 1225.19 | D30: 1606.93 | E30: 1968.44 | F30: 2082.43 | G30: 2118.41 | H30: 2390.52 | I30: 2998.67 | J30: 3932.84 | K30: 3314.5
A31: Dividend Amount | B31: 607.45 | C31: 829.21 | D31: 1108.83 | E31: 3297.56 | F31: 1928.4 | G31: 1928.4 | H31: 2121.24 | I31: 1677.71 | J31: 3104.72 | K31: 2603.34
A40: Quarters
A41: Report Date | B41: 45199 | C41: 45291 | D41: 45382 | E41: 45473 | F41: 45565 | G41: 45657 | H41: 45747 | I41: 45838 | J41: 45930 | K41: 46022
A42: Sales | B42: 5036.82 | C42: 4600.42 | D42: 5267.59 | E42: 4813.95 | F42: 5104 | G42: 4779.73 | H42: 5503.88 | I42: 5096.16 | J42: 5643.61 | K42: 5667.04
A43: Expenses | B43: 3811.95 | C43: 3505.3 | D43: 3917.54 | E43: 3699.62 | F43: 3936.27 | G43: 3677.04 | H43: 4114.92 | I43: 3995.9 | J43: 4406.97 | K43: 4464.97
A44: Other Income | B44: 139.69 | C44: -77 | D44: 36.83 | E44: 39.12 | F44: 297.68 | G44: 4.44 | H44: 8.44 | I44: 4.04 | J44: 1.64 | K44: 168.66
A45: Depreciation | B45: 111.16 | C45: 108.69 | D45: 110.1 | E45: 112.71 | F45: 121.6 | G45: 150.27 | H45: 155.34 | I45: 156.94 | J45: 163.35 | K45: 174.41
A46: Interest | B46: 31.38 | C46: 22.95 | D46: 26.2 | E46: 31.68 | F46: 32.22 | G46: 34.6 | H46: 37.5 | I46: 46.89 | J46: 46.41 | K46: 28.25
A47: Profit before tax | B47: 1222.02 | C47: 886.48 | D47: 1250.58 | E47: 1009.06 | F47: 1311.59 | G47: 922.26 | H47: 1204.56 | I47: 900.47 | J47: 1028.52 | K47: 1168.07
A48: Tax | B48: 313.94 | C48: 230.87 | D48: 316.41 | E48: 262.46 | F48: 325.23 | G48: 226.13 | H48: 319.15 | I48: 241.24 | J48: 275.32 | K48: 150.01
A49: Net profit | B49: 908.08 | C49: 655.61 | D49: 934.17 | E49: 746.6 | F49: 986.36 | G49: 696.13 | H49: 885.41 | I49: 659.23 | J49: 753.2 | K49: 1018.06
A50: Operating Profit | B50: 1224.87 | C50: 1095.12 | D50: 1350.05 | E50: 1114.33 | F50: 1167.73 | G50: 1102.69 | H50: 1388.96 | I50: 1100.26 | J50: 1236.64 | K50: 1202.07
A55: BALANCE SHEET
A56: Report Date | B56: 42735 | C56: 43100 | D56: 43465 | E56: 43830 | F56: 44196 | G56: 44561 | H56: 44926 | I56: 45291 | J56: 45382 | K56: 45747
A57: Equity Share Capital | B57: 96.42 | C57: 96.42 | D57: 96.42 | E57: 96.42 | F57: 96.42 | G57: 96.42 | H57: 96.42 | I57: 96.42 | J57: 96.42 | K57: 96.42
A58: Reserves | B58: 3185.91 | C58: 3324.17 | D58: 3577.32 | E58: 1822.45 | F58: 1922.92 | G58: 1849.96 | H58: 2362.75 | I58: 2362.75 | J58: 3244.47 | K58: 4020.73
...

Sheet Historical FS
A1: Historical Financial Data - TATA MOTORS LTD
A2: Years | B2: 42705 | C2: =B2+365 -> 43070 | D2: =C2+365 -> 43435 | E2: =D2+365 -> 43800 | F2: =E2+366 -> 44166 | G2: =F2+366 -> 44532 | H2: =G2+366 -> 44898 | I2: =H2+366 -> 45264 | J2: 45352 | K2: =J2+366 -> 45718
A3: INCOME STATEMENT
A4: SALES | B4: =IFERROR('Data Sheet'!B17,0) -> 9141.34 | C4: =IFERROR('Data Sheet'!C17,0) -> 10009.6 | D4: =IFERROR('Data Sheet'!D17,0) -> 11292.27 | E4: =IFERROR('Data Sheet'!E17,0) -> 12368.9 | F4: =IFERROR('Data Sheet'!F17,0) -> 13350.03 | G4: =IFERROR('Data Sheet'!G17,0) -> 14740.59 | H4: =IFERROR('Data Sheet'!H17,0) -> 16896.96 | I4: =IFERROR('Data Sheet'!I17,0) -> 19126.3 | ... K4: =IFERROR('Data Sheet'!K17,0) -> 20201.56
A5: SALES GROWTH | C5: =C4/B4 -> 1.0949817 | D5: =D4/C4 -> 1.128144 | E5: =E4/D4 -> 1.0953422 | F5: =F4/E4 -> 1.0793223 | G5: =G4/F4 -> 1.1041616 | H5: =H4/G4 -> 1.1462879 | I5: =I4/H4 -> 1.1319373 | J5: =J4/I4 -> 1.2754108 | K5: =K4/J4 -> 0.82814016
A7: COGS | B7: =IFERROR(SUM('Data Sheet'!B18,'Data Sheet'!B20,'Data Sheet'!B21,'Data Sheet'!B22)-1*'Data Sheet'!B19,0) -> 5204.81 | C7: =IFERROR(SUM('Data Sheet'!C18,'Data Sheet'!C20,'Data Sheet'!C21,'Data Sheet'!C22)-1*'Data Sheet'!C19,0) -> 5821.16 | D7: =IFERROR(SUM('Data Sheet'!D18,'Data Sheet'!D20,'Data Sheet'!D21,'Data Sheet'!D22)-1*'Data Sheet'!D19,0) -> 6241.4 | E7: =IFERROR(SUM('Data Sheet'!E18,'Data Sheet'!E20,'Data Sheet'!E21,'Data Sheet'!E22)-1*'Data Sheet'!E19,0) -> 7003.97 | F7: =IFERROR(SUM('Data Sheet'!F18,'Data Sheet'!F20,'Data Sheet'!F21,'Data Sheet'!F22)-1*'Data Sheet'!F19,0) -> 7687.4 | G7: =IFERROR(SUM('Data Sheet'!G18,'Data Sheet'!G20,'Data Sheet'!G21,'Data Sheet'!G22)-1*'Data Sheet'!G19,0) -> 8521.15 | H7: =IFERROR(SUM('Data Sheet'!H18,'Data Sheet'!H20,'Data Sheet'!H21,'Data Sheet'!H22)-1*'Data Sheet'!H19,0) -> 10221.7 | I7: =IFERROR(SUM('Data Sheet'!I18,'Data Sheet'!I20,'Data Sheet'!I21,'Data Sheet'!I22)-1*'Data Sheet'!I19,0) -> 10281.89 | ... K7: =IFERROR(SUM('Data Sheet'!K18,'Data Sheet'!K20,'Data Sheet'!K21,'Data Sheet'!K22)-1*'Data Sheet'!K19,0) -> 11647.13
A8: COGS % SALES | B8: =B7/B4 -> 0.56937057 | C8: =C7/C4 -> 0.5815577 | D8: =D7/D4 -> 0.55271438 | E8: =E7/E4 -> 0.5662565 | F8: =F7/F4 -> 0.57583391 | G8: =G7/G4 -> 0.57807388 | H8: =H7/H4 -> 0.60494314 | I8: =I7/I4 -> 0.53757862 | ... K8: =K7/K4 -> 0.57654607
A10: GROSS PROFIT | B10: =B4-B7 -> 3936.53 | C10: =C4-C7 -> 4188.44 | D10: =D4-D7 -> 5050.87 | E10: =E4-E7 -> 5364.93 | F10: =F4-F7 -> 5662.63 | G10: =G4-G7 -> 6219.44 | H10: =H4-H7 -> 6675.26 | I10: =I4-I7 -> 8844.41 | ... K10: =K4-K7 -> 8554.43
A11: GROSS PROFIT MARGIN
A13: SELLING AND GEN. EXP | B13: =IFERROR(SUM('Data Sheet'!B23,'Data Sheet'!B24),0) -> 2086.69 | C13: =IFERROR(SUM('Data Sheet'!C23,'Data Sheet'!C24),0) -> 2091.91 | D13: =IFERROR(SUM('Data Sheet'!D23,'Data Sheet'!D24),0) -> 2433.22 | E13: =IFERROR(SUM('Data Sheet'!E23,'Data Sheet'!E24),0) -> 2439.05 | F13: =IFERROR(SUM('Data Sheet'!F23,'Data Sheet'!F24),0) -> 2461.13 | G13: =IFERROR(SUM('Data Sheet'!G23,'Data Sheet'!G24),0) -> 2657.04 | H13: =IFERROR(SUM('Data Sheet'!H23,'Data Sheet'!H24),0) -> 2968.97 | I13: =IFERROR(SUM('Data Sheet'!I23,'Data Sheet'!I24),0) -> 4373.42 | ... K13: =IFERROR(SUM('Data Sheet'!K23,'Data Sheet'!K24),0) -> 3783.1
A14: S & G % SALES | B14: =B13/B4 -> 0.2282696 | C14: =C13/C4 -> 0.20899037 | D14: =D13/D4 -> 0.2154766 | E14: =E13/E4 -> 0.19719215 | F14: =F13/F4 -> 0.18435389 | G14: =G13/G4 -> 0.1802533 | H14: =H13/H4 -> 0.17571031 | I14: =I13/I4 -> 0.22866001 | ... K14: =K13/K4 -> 0.18726772
A16: EBITDA | B16: =B10-B13 -> 1849.84 | C16: =C10-C13 -> 2096.53 | D16: =D10-D13 -> 2617.65 | E16: =E10-E13 -> 2925.88 | F16: =F10-F13 -> 3201.5 | G16: =G10-G13 -> 3562.4 | H16: =H10-H13 -> 3706.29 | I16: =I10-I13 -> 4470.99 | ... K16: =K10-K13 -> 4771.33
A17: EBITDA MARGIN | B17: =B16/B4 -> 0.20235983 | C17: =C16/C4 -> 0.20945193 | D17: =D16/D4 -> 0.23180902 | E17: =E16/E4 -> 0.23655135 | F17: =F16/F4 -> 0.2398122 | G17: =G16/G4 -> 0.24167282 | H17: =H16/H4 -> 0.21934656 | I17: =I16/I4 -> 0.23376137 | ... K17: =K16/K4 -> 0.23618622
A19: INTEREST | B19: =IFERROR('Data Sheet'!B27,0) -> 90.91 | C19: =IFERROR('Data Sheet'!C27,0) -> 91.9 | D19: =IFERROR('Data Sheet'!D27,0) -> 111.95 | E19: =IFERROR('Data Sheet'!E27,0) -> 129.12 | F19: =IFERROR('Data Sheet'!F27,0) -> 164.18 | G19: =IFERROR('Data Sheet'!G27,0) -> 201.68 | H19: =IFERROR('Data Sheet'!H27,0) -> 154.57 | I19: =IFERROR('Data Sheet'!I27,0) -> 119.29 | ... K19: =IFERROR('Data Sheet'!K27,0) -> 136
A20: INTEREST % SALES | B20: =B19/B4 -> 0.0099449315 | C20: =C19/C4 -> 0.0091811861 | D20: =D19/D4 -> 0.0099138614 | E20: =E19/E4 -> 0.010439085 | F20: =F19/F4 -> 0.0122981 | G20: =G19/G4 -> 0.013681949 | H20: =H19/H4 -> 0.0091477994 | I20: =I19/I4 -> 0.0062369617 | ... K20: =K19/K4 -> 0.0067321534
A22: DEPRICIATION | B22: =IFERROR('Data Sheet'!B26,0) -> 353.67 | C22: =IFERROR('Data Sheet'!C26,0) -> 342.25 | D22: =IFERROR('Data Sheet'!D26,0) -> 335.67 | E22: =IFERROR('Data Sheet'!E26,0) -> 370.15 | F22: =IFERROR('Data Sheet'!F26,0) -> 370.38 | G22: =IFERROR('Data Sheet'!G26,0) -> 391.02 | H22: =IFERROR('Data Sheet'!H26,0) -> 403.01 | I22: =IFERROR('Data Sheet'!I26,0) -> 428.91 | ... K22: =IFERROR('Data Sheet'!K26,0) -> 539.92
A23: DEP % SALES | B23: =B22/B4 -> 0.038689076 | C23: =C22/C4 -> 0.034192176 | D23: =D22/D4 -> 0.029725644 | E23: =E22/E4 -> 0.029925862 | F23: =F22/F4 -> 0.027743758 | G23: =G22/G4 -> 0.026526754 | H23: =H22/H4 -> 0.023851036 | I23: =I22/I4 -> 0.022425142 | ... K23: =K22/K4 -> 0.026726649
A25: EARNING BEFORE TAX | B25: =IFERROR('Data Sheet'!B28,0) -> 1545.38 | C25: =IFERROR('Data Sheet'!C28,0) -> 1839.3 | D25: =IFERROR('Data Sheet'!D28,0) -> 2428.95 | E25: =IFERROR('Data Sheet'!E28,0) -> 2673.49 | F25: =IFERROR('Data Sheet'!F28,0) -> 2812.79 | G25: =IFERROR('Data Sheet'!G28,0) -> 2857.32 | H25: =IFERROR('Data Sheet'!H28,0) -> 3255.97 | I25: =IFERROR('Data Sheet'!I28,0) -> 4038.29 | ... K25: =IFERROR('Data Sheet'!K28,0) -> 4447.47
A26: EBT % SALES | B26: =B25/B4 -> 0.16905399 | C26: =C25/C4 -> 0.1837536 | D26: =D25/D4 -> 0.21509847 | E26: =E25/E4 -> 0.21614614 | F26: =F25/F4 -> 0.21069541 | G26: =G25/G4 -> 0.19384027 | H26: =H25/H4 -> 0.19269561 | I26: =I25/I4 -> 0.21113807 | ... K26: =K25/K4 -> 0.22015478
A28: TAX | B28: =IFERROR('Data Sheet'!B29,0) -> 544.02 | C28: =IFERROR('Data Sheet'!C29,0) -> 614.11 | D28: =IFERROR('Data Sheet'!D29,0) -> 822.02 | E28: =IFERROR('Data Sheet'!E29,0) -> 705.05 | F28: =IFERROR('Data Sheet'!F29,0) -> 730.36 | G28: =IFERROR('Data Sheet'!G29,0) -> 738.91 | H28: =IFERROR('Data Sheet'!H29,0) -> 865.45 | I28: =IFERROR('Data Sheet'!I29,0) -> 1039.62 | ... K28: =IFERROR('Data Sheet'!K29,0) -> 1132.97
A29: EFFECTIVE TAX RATE | B29: =B28/B4 -> 0.059512063 | C29: =C28/C4 -> 0.061352102 | D29: =D28/D4 -> 0.07279493 | E29: =E28/E4 -> 0.057001835 | F29: =F28/F4 -> 0.054708491 | G29: =G28/G4 -> 0.050127573 | H29: =H28/H4 -> 0.051219273 | I29: =I28/I4 -> 0.054355521 | ... K29: =K28/K4 -> 0.056083293
A31: NET PROFIT | B31: =B25-B28 -> 1001.36 | C31: =C25-C28 -> 1225.19 | D31: =D25-D28 -> 1606.93 | E31: =E25-E28 -> 1968.44 | F31: =F25-F28 -> 2082.43 | G31: =G25-G28 -> 2118.41 | H31: =H25-H28 -> 2390.52 | I31: =I25-I28 -> 2998.67 | ... K31: =K25-K28 -> 3314.5
A32: NET MARGIN | B32: =B31/B4 -> 0.10954193 | C32: =C31/C4 -> 0.12240149 | D32: =D31/D4 -> 0.14230354 | E32: =E31/E4 -> 0.15914431 | F32: =F31/F4 -> 0.15598692 | G32: =G31/G4 -> 0.1437127 | H32: =H31/H4 -> 0.14147634 | I32: =I31/I4 -> 0.15678255 | ... K32: =K31/K4 -> 0.16407149
A34: No. of Equity Shareholders Outstanding | B34: =IFERROR('Data Sheet'!B93,0) -> 192.8 | C34: =IFERROR('Data Sheet'!C93,0) -> 192.8 | D34: =IFERROR('Data Sheet'!D93,0) -> 192.8 | E34: =IFERROR('Data Sheet'!E93,0) -> 192.8 | F34: =IFERROR('Data Sheet'!F93,0) -> 192.8 | G34: =IFERROR('Data Sheet'!G93,0) -> 192.8 | H34: =IFERROR('Data Sheet'!H93,0) -> 192.8 | I34: =IFERROR('Data Sheet'!I93,0) -> 192.8 | ... K34: =IFERROR('Data Sheet'!K93,0) -> 192.83
A36: EPS | B36: =B31/B34 -> 5.1937759 | C36: =C31/C34 -> 6.3547199 | D36: =D31/D34 -> 8.3346992 | E36: =E31/E34 -> 10.209751 | F36: =F31/F34 -> 10.800985 | G36: =G31/G34 -> 10.987604 | H36: =H31/H34 -> 12.398963 | I36: =I31/I34 -> 15.553268 | ... K36: =K31/K34 -> 17.188715
A37: EPS GROWTH
A38: DPS | B38: =IFERROR('Data Sheet'!B31/'Historical FS'!B34,0) -> 3.1506743 | C38: =IFERROR('Data Sheet'!C31/'Historical FS'!C34,0) -> 4.3008817 | D38: =IFERROR('Data Sheet'!D31/'Historical FS'!D34,0) -> 5.7511929 | E38: =IFERROR('Data Sheet'!E31/'Historical FS'!E34,0) -> 17.103527 | F38: =IFERROR('Data Sheet'!F31/'Historical FS'!F34,0) -> 10.002075 | G38: =IFERROR('Data Sheet'!G31/'Historical FS'!G34,0) -> 10.002075 | H38: =IFERROR('Data Sheet'!H31/'Historical FS'!H34,0) -> 11.002282 | I38: =IFERROR('Data Sheet'!I31/'Historical FS'!I34,0) -> 8.7018154 | ... K38: =IFERROR('Data Sheet'!K31/'Historical FS'!K34,0) -> 13.5007
A39: DPS RATIO | B39: =IFERROR(B38/B36,0) -> 0.60662499 | C39: =IFERROR(C38/C36,0) -> 0.67680115 | D39: =IFERROR(D38/D36,0) -> 0.69003006 | E39: =IFERROR(E38/E36,0) -> 1.6752149 | F39: =IFERROR(F38/F36,0) -> 0.92603353 | G39: =IFERROR(G38/G36,0) -> 0.91030537 | H39: =IFERROR(H38/H36,0) -> 0.88735505 | I39: =IFERROR(I38/I36,0) -> 0.5594847 | ... K39: =IFERROR(K38/K36,0) -> 0.78543973
A41: RETAINED EARNING | B41: =IFERROR(1-B39,0) -> 0.39337501 | C41: =IFERROR(1-C39,0) -> 0.32319885 | D41: =IFERROR(1-D39,0) -> 0.30996994 | E41: =IFERROR(1-E39,0) -> -0.67521489 | F41: =IFERROR(1-F39,0) -> 0.073966472 | G41: =IFERROR(1-G39,0) -> 0.089694629 | H41: =IFERROR(1-H39,0) -> 0.11264495 | I41: =IFERROR(1-I39,0) -> 0.4405153 | ... K41: =IFERROR(1-K39,0) -> 0.21456027
B42: =IFERROR(IF(B36>B38,1-B39,0),0) -> 0.39337501 | C42: =IFERROR(IF(C36>C38,1-C39,0),0) -> 0.32319885 | D42: =IFERROR(IF(D36>D38,1-D39,0),0) -> 0.30996994 | E42: =IFERROR(IF(E36>E38,1-E39,0),0) -> 0 | F42: =IFERROR(IF(F36>F38,1-F39,0),0) -> 0.073966472 | G42: =IFERROR(IF(G36>G38,1-G39,0),0) -> 0.089694629 | H42: =IFERROR(IF(H36>H38,1-H39,0),0) -> 0.11264495 | I42: =IFERROR(IF(I36>I38,1-I39,0),0) -> 0.4405153 | ... K42: =IFERROR(IF(K36>K38,1-K39,0),0) -> 0.21456027
A44: BALANCE SHEET
A45: Equity Share Capital | B45: =IFERROR('Data Sheet'!B57,0) -> 96.42 | C45: =IFERROR('Data Sheet'!C57,0) -> 96.42 | D45: =IFERROR('Data Sheet'!D57,0) -> 96.42 | E45: =IFERROR('Data Sheet'!E57,0) -> 96.42 | F45: =IFERROR('Data Sheet'!F57,0) -> 96.42 | G45: =IFERROR('Data Sheet'!G57,0) -> 96.42 | H45: =IFERROR('Data Sheet'!H57,0) -> 96.42 | I45: =IFERROR('Data Sheet'!I57,0) -> 96.42 | ... K45: =IFERROR('Data Sheet'!K57,0) -> 96.42
A46: Reserves | B46: =IFERROR('Data Sheet'!B58,0) -> 3185.91 | C46: =IFERROR('Data Sheet'!C58,0) -> 3324.17 | D46: =IFERROR('Data Sheet'!D58,0) -> 3577.32 | E46: =IFERROR('Data Sheet'!E58,0) -> 1822.45 | F46: =IFERROR('Data Sheet'!F58,0) -> 1922.92 | G46: =IFERROR('Data Sheet'!G58,0) -> 1849.96 | H46: =IFERROR('Data Sheet'!H58,0) -> 2362.75 | I46: =IFERROR('Data Sheet'!I58,0) -> 2362.75 | ... K46: =IFERROR('Data Sheet'!K58,0) -> 4020.73
A47: Borrowings | B47: =IFERROR('Data Sheet'!B59,0) -> 33.15 | C47: =IFERROR('Data Sheet'!C59,0) -> 35.14 | D47: =IFERROR('Data Sheet'!D59,0) -> 35.14 | E47: =IFERROR('Data Sheet'!E59,0) -> 188.94 | F47: =IFERROR('Data Sheet'!F59,0) -> 147.49 | G47: =IFERROR('Data Sheet'!G59,0) -> 266.46 | H47: =IFERROR('Data Sheet'!H59,0) -> 270.52 | I47: =IFERROR('Data Sheet'!I59,0) -> 270.52 | ... K47: =IFERROR('Data Sheet'!K59,0) -> 1166.85
A48: Other Liabilities | B48: =IFERROR('Data Sheet'!B60,0) -> 3494.98 | C48: =IFERROR('Data Sheet'!C60,0) -> 3906.86 | D48: =IFERROR('Data Sheet'!D60,0) -> 4379.2 | E48: =IFERROR('Data Sheet'!E60,0) -> 5065.13 | F48: =IFERROR('Data Sheet'!F60,0) -> 5732.9 | G48: =IFERROR('Data Sheet'!G60,0) -> 6021.29 | H48: =IFERROR('Data Sheet'!H60,0) -> 6249.05 | I48: =IFERROR('Data Sheet'!I60,0) -> 6249.05 | ... K48: =IFERROR('Data Sheet'!K60,0) -> 7039.89
A49: Total Liabilities | B49: =SUM(B45:B48) -> 6810.46 | C49: =SUM(C45:C48) -> 7362.59 | D49: =SUM(D45:D48) -> 8088.08 | E49: =SUM(E45:E48) -> 7172.94 | F49: =SUM(F45:F48) -> 7899.73 | G49: =SUM(G45:G48) -> 8234.13 | H49: =SUM(H45:H48) -> 8978.74 | I49: =SUM(I45:I48) -> 8978.74 | ... K49: =SUM(K45:K48) -> 12323.89
A51: Fixed Asset Net Block | B51: =IFERROR('Data Sheet'!B62,0) -> 2730.14 | C51: =IFERROR('Data Sheet'!C62,0) -> 2616.18 | D51: =IFERROR('Data Sheet'!D62,0) -> 2400.62 | E51: =IFERROR('Data Sheet'!E62,0) -> 2341.45 | F51: =IFERROR('Data Sheet'!F62,0) -> 2179.41 | G51: =IFERROR('Data Sheet'!G62,0) -> 2994.67 | H51: =IFERROR('Data Sheet'!H62,0) -> 3043.7 | I51: =IFERROR('Data Sheet'!I62,0) -> 3043.7 | ... K51: =IFERROR('Data Sheet'!K62,0) -> 5473.61
A52: Capital Work in Progress | B52: =IFERROR('Data Sheet'!B63,0) -> 188.17 | C52: =IFERROR('Data Sheet'!C63,0) -> 94.16 | D52: =IFERROR('Data Sheet'!D63,0) -> 105.2 | E52: =IFERROR('Data Sheet'!E63,0) -> 143.3 | F52: =IFERROR('Data Sheet'!F63,0) -> 638.58 | G52: =IFERROR('Data Sheet'!G63,0) -> 246.23 | H52: =IFERROR('Data Sheet'!H63,0) -> 358.36 | I52: =IFERROR('Data Sheet'!I63,0) -> 358.36 | ... K52: =IFERROR('Data Sheet'!K63,0) -> 1172.56
A53: Investments | B53: =IFERROR('Data Sheet'!B64,0) -> 1755.66 | C53: =IFERROR('Data Sheet'!C64,0) -> 1978.87 | D53: =IFERROR('Data Sheet'!D64,0) -> 2658.49 | E53: =IFERROR('Data Sheet'!E64,0) -> 1751.05 | F53: =IFERROR('Data Sheet'!F64,0) -> 1463.77 | G53: =IFERROR('Data Sheet'!G64,0) -> 773.98 | H53: =IFERROR('Data Sheet'!H64,0) -> 777.54 | I53: =IFERROR('Data Sheet'!I64,0) -> 777.54 | ... K53: =IFERROR('Data Sheet'!K64,0) -> 705.6
A54: Other Assets | B54: ='Data Sheet'!B65-SUM('Data Sheet'!B67:B69) -> 218.5 | C54: ='Data Sheet'!C65-SUM('Data Sheet'!C67:C69) -> 224.52 | D54: ='Data Sheet'!D65-SUM('Data Sheet'!D67:D69) -> 223.57 | E54: ='Data Sheet'!E65-SUM('Data Sheet'!E67:E69) -> 221.69 | F54: ='Data Sheet'!F65-SUM('Data Sheet'!F67:F69) -> 266.69 | G54: ='Data Sheet'!G65-SUM('Data Sheet'!G67:G69) -> 1725.22 | H54: ='Data Sheet'!H65-SUM('Data Sheet'!H67:H69) -> 1732.93 | I54: ='Data Sheet'!I65-SUM('Data Sheet'!I67:I69) -> 1732.93 | ... K54: ='Data Sheet'!K65-SUM('Data Sheet'!K67:K69) -> 1663.18
...

Sheet Ratio Analysis
A1: Ratio Analysis-TATA MOTORS LTD
A2: Years | B2: 42705 | C2: =B2+365 -> 43070 | D2: =C2+365 -> 43435 | E2: =D2+365 -> 43800 | F2: =E2+366 -> 44166 | G2: =F2+366 -> 44532 | H2: =G2+366 -> 44898 | I2: =H2+366 -> 45264 | J2: 45352 | K2: =J2+366 -> 45718 | M2: Mean | N2: Median
A3: Sales Growth | B3: =IFERROR('Historical FS'!B4,0) -> 9141.34 | C3: =IFERROR('Historical FS'!C4,0) -> 10009.6 | D3: =IFERROR('Historical FS'!D4,0) -> 11292.27 | E3: =IFERROR('Historical FS'!E4,0) -> 12368.9 | F3: =IFERROR('Historical FS'!F4,0) -> 13350.03 | G3: =IFERROR('Historical FS'!G4,0) -> 14740.59 | H3: =IFERROR('Historical FS'!H4,0) -> 16896.96 | I3: =IFERROR('Historical FS'!I4,0) -> 19126.3 | ... K3: =IFERROR('Historical FS'!K4,0) -> 20201.56
A4: Sales Growth | C4: =C3/B3 -> 1.0949817 | D4: =D3/C3 -> 1.128144 | E4: =E3/D3 -> 1.0953422 | F4: =F3/E3 -> 1.0793223 | G4: =G3/F3 -> 1.1041616 | H4: =H3/G3 -> 1.1462879 | I4: =I3/H3 -> 1.1319373 | J4: =J3/I3 -> 1.2754108 | K4: =K3/J3 -> 0.82814016 | M4: =IFERROR(AVERAGE(C4:K4),0) -> 1.098192 | N4: =IFERROR(MEDIAN(C4:K4),0) -> 1.1041616
A5: EBITDA Growth | C5: =IFERROR('Historical FS'!C16/'Historical FS'!B16-1,0) -> 0.13335748 | D5: =IFERROR('Historical FS'!D16/'Historical FS'!C16-1,0) -> 0.2485631 | E5: =IFERROR('Historical FS'!E16/'Historical FS'!D16-1,0) -> 0.11775065 | F5: =IFERROR('Historical FS'!F16/'Historical FS'!E16-1,0) -> 0.094200719 | G5: =IFERROR('Historical FS'!G16/'Historical FS'!F16-1,0) -> 0.11272841 | H5: =IFERROR('Historical FS'!H16/'Historical FS'!G16-1,0) -> 0.040391309 | I5: =IFERROR('Historical FS'!I16/'Historical FS'!H16-1,0) -> 0.20632492 | J5: =IFERROR('Historical FS'!J16/'Historical FS'!I16-1,0) -> 0.30689624 | K5: =IFERROR('Historical FS'!K16/'Historical FS'!J16-1,0) -> -0.18342769 | M5: =IFERROR(AVERAGE(C5:K5),0) -> 0.11964279 | N5: =IFERROR(MEDIAN(C5:K5),0) -> 0.11775065
A6: EBIT Growth | C6: =IFERROR('Historical FS'!C25/'Historical FS'!B25-1,0) -> 0.1901927 | D6: =IFERROR('Historical FS'!D25/'Historical FS'!C25-1,0) -> 0.32058392 | E6: =IFERROR('Historical FS'!E25/'Historical FS'!D25-1,0) -> 0.10067725 | F6: =IFERROR('Historical FS'!F25/'Historical FS'!E25-1,0) -> 0.052104178 | G6: =IFERROR('Historical FS'!G25/'Historical FS'!F25-1,0) -> 0.015831257 | H6: =IFERROR('Historical FS'!H25/'Historical FS'!G25-1,0) -> 0.13951885 | I6: =IFERROR('Historical FS'!I25/'Historical FS'!H25-1,0) -> 0.24027248 | J6: =IFERROR('Historical FS'!J25/'Historical FS'!I25-1,0) -> 0.30968058 | K6: =IFERROR('Historical FS'!K25/'Historical FS'!J25-1,0) -> -0.1590888 | M6: =IFERROR(AVERAGE(C6:K6),0) -> 0.13441916 | N6: =IFERROR(MEDIAN(C6:K6),0) -> 0.13951885
A7: Net Profit Growth | C7: =IFERROR('Historical FS'!C31/'Historical FS'!B31-1,0) -> 0.223526 | D7: =IFERROR('Historical FS'!D31/'Historical FS'!C31-1,0) -> 0.31157616 | E7: =IFERROR('Historical FS'!E31/'Historical FS'!D31-1,0) -> 0.22496935 | F7: =IFERROR('Historical FS'!F31/'Historical FS'!E31-1,0) -> 0.057908801 | G7: =IFERROR('Historical FS'!G31/'Historical FS'!F31-1,0) -> 0.017277892 | H7: =IFERROR('Historical FS'!H31/'Historical FS'!G31-1,0) -> 0.12845011 | I7: =IFERROR('Historical FS'!I31/'Historical FS'!H31-1,0) -> 0.25440072 | J7: =IFERROR('Historical FS'!J31/'Historical FS'!I31-1,0) -> 0.31152811 | K7: =IFERROR('Historical FS'!K31/'Historical FS'!J31-1,0) -> -0.1572248 | M7: =IFERROR(AVERAGE(C7:K7),0) -> 0.15249026 | N7: =IFERROR(MEDIAN(C7:K7),0) -> 0.223526
A8: Dividend Growth | C8: =IFERROR('Historical FS'!C38/'Historical FS'!B38-1,0) -> 0.36506708 | D8: =IFERROR('Historical FS'!D38/'Historical FS'!C38-1,0) -> 0.33721253 | E8: =IFERROR('Historical FS'!E38/'Historical FS'!D38-1,0) -> 1.9739094 | F8: =IFERROR('Historical FS'!F38/'Historical FS'!E38-1,0) -> -0.41520397 | G8: =IFERROR('Historical FS'!G38/'Historical FS'!F38-1,0) -> 0 | H8: =IFERROR('Historical FS'!H38/'Historical FS'!G38-1,0) -> 0.1 | I8: =IFERROR('Historical FS'!I38/'Historical FS'!H38-1,0) -> -0.20908997 | J8: =IFERROR('Historical FS'!J38/'Historical FS'!I38-1,0) -> 0.85028222 | K8: =IFERROR('Historical FS'!K38/'Historical FS'!J38-1,0) -> -0.1614896 | M8: =IFERROR(AVERAGE(C8:K8),0) -> 0.31563197 | N8: =IFERROR(MEDIAN(C8:K8),0) -> 0.1
A10: Gross Margin | B10: =IFERROR('Historical FS'!B10/'Historical FS'!B4,0) -> 0.43062943 | C10: =IFERROR('Historical FS'!C10/'Historical FS'!C4,0) -> 0.4184423 | D10: =IFERROR('Historical FS'!D10/'Historical FS'!D4,0) -> 0.44728562 | E10: =IFERROR('Historical FS'!E10/'Historical FS'!E4,0) -> 0.4337435 | F10: =IFERROR('Historical FS'!F10/'Historical FS'!F4,0) -> 0.42416609 | G10: =IFERROR('Historical FS'!G10/'Historical FS'!G4,0) -> 0.42192612 | H10: =IFERROR('Historical FS'!H10/'Historical FS'!H4,0) -> 0.39505686 | I10: =IFERROR('Historical FS'!I10/'Historical FS'!I4,0) -> 0.46242138 | ... K10: =IFERROR('Historical FS'!K10/'Historical FS'!K4,0) -> 0.42345393 | M10: =IFERROR(AVERAGE(B10:K10),0) -> 0.42790411 | N10: =IFERROR(MEDIAN(B10:K10),0) -> 0.42381001
A11: EBITDA Margin | B11: =IFERROR('Historical FS'!B17,0) -> 0.20235983 | C11: =IFERROR('Historical FS'!C17,0) -> 0.20945193 | D11: =IFERROR('Historical FS'!D17,0) -> 0.23180902 | E11: =IFERROR('Historical FS'!E17,0) -> 0.23655135 | F11: =IFERROR('Historical FS'!F17,0) -> 0.2398122 | G11: =IFERROR('Historical FS'!G17,0) -> 0.24167282 | H11: =IFERROR('Historical FS'!H17,0) -> 0.21934656 | I11: =IFERROR('Historical FS'!I17,0) -> 0.23376137 | ... K11: =IFERROR('Historical FS'!K17,0) -> 0.23618622 | M11: =IFERROR(AVERAGE(B11:K11),0) -> 0.22904834 | N11: =IFERROR(MEDIAN(B11:K11),0) -> 0.23497379
A12: EBIT Margin | B12: =IFERROR((('Historical FS'!B16-'Historical FS'!B22)/'Historical FS'!B4),0) -> 0.16367075 | C12: =IFERROR((('Historical FS'!C16-'Historical FS'!C22)/'Historical FS'!C4),0) -> 0.17525975 | D12: =IFERROR((('Historical FS'!D16-'Historical FS'!D22)/'Historical FS'!D4),0) -> 0.20208337 | E12: =IFERROR((('Historical FS'!E16-'Historical FS'!E22)/'Historical FS'!E4),0) -> 0.20662549 | F12: =IFERROR((('Historical FS'!F16-'Historical FS'!F22)/'Historical FS'!F4),0) -> 0.21206844 | G12: =IFERROR((('Historical FS'!G16-'Historical FS'!G22)/'Historical FS'!G4),0) -> 0.21514607 | H12: =IFERROR((('Historical FS'!H16-'Historical FS'!H22)/'Historical FS'!H4),0) -> 0.19549552 | I12: =IFERROR((('Historical FS'!I16-'Historical FS'!I22)/'Historical FS'!I4),0) -> 0.21133622 | ... K12: =IFERROR((('Historical FS'!K16-'Historical FS'!K22)/'Historical FS'!K4),0) -> 0.20945957 | M12: =IFERROR(AVERAGE(B12:K12),0) -> 0.2007403 | N12: =IFERROR(MEDIAN(B12:K12),0) -> 0.20804253
A13: EBT Margin | B13: =IFERROR('Historical FS'!B26,0) -> 0.16905399 | C13: =IFERROR('Historical FS'!C26,0) -> 0.1837536 | D13: =IFERROR('Historical FS'!D26,0) -> 0.21509847 | E13: =IFERROR('Historical FS'!E26,0) -> 0.21614614 | F13: =IFERROR('Historical FS'!F26,0) -> 0.21069541 | G13: =IFERROR('Historical FS'!G26,0) -> 0.19384027 | H13: =IFERROR('Historical FS'!H26,0) -> 0.19269561 | I13: =IFERROR('Historical FS'!I26,0) -> 0.21113807 | ... K13: =IFERROR('Historical FS'!K26,0) -> 0.22015478 | M13: =IFERROR(AVERAGE(B13:K13),0) -> 0.20293876 | N13: =IFERROR(MEDIAN(B13:K13),0) -> 0.21091674
A14: Net Profit Margin | B14: =IFERROR('Historical FS'!B32,0) -> 0.10954193 | C14: =IFERROR('Historical FS'!C32,0) -> 0.12240149 | D14: =IFERROR('Historical FS'!D32,0) -> 0.14230354 | E14: =IFERROR('Historical FS'!E32,0) -> 0.15914431 | F14: =IFERROR('Historical FS'!F32,0) -> 0.15598692 | G14: =IFERROR('Historical FS'!G32,0) -> 0.1437127 | H14: =IFERROR('Historical FS'!H32,0) -> 0.14147634 | I14: =IFERROR('Historical FS'!I32,0) -> 0.15678255 | ... K14: =IFERROR('Historical FS'!K32,0) -> 0.16407149 | M14: =IFERROR(AVERAGE(B14:K14),0) -> 0.14566436 | N14: =IFERROR(MEDIAN(B14:K14),0) -> 0.14984981
A16: Sales Expenses % Sales | B16: =IFERROR('Historical FS'!B14,0) -> 0.2282696 | C16: =IFERROR('Historical FS'!C14,0) -> 0.20899037 | D16: =IFERROR('Historical FS'!D14,0) -> 0.2154766 | E16: =IFERROR('Historical FS'!E14,0) -> 0.19719215 | F16: =IFERROR('Historical FS'!F14,0) -> 0.18435389 | G16: =IFERROR('Historical FS'!G14,0) -> 0.1802533 | H16: =IFERROR('Historical FS'!H14,0) -> 0.17571031 | I16: =IFERROR('Historical FS'!I14,0) -> 0.22866001 | ... K16: =IFERROR('Historical FS'!K14,0) -> 0.18726772 | M16: =IFERROR(AVERAGE(B16:K16),0) -> 0.19885577 | N16: =IFERROR(MEDIAN(B16:K16),0) -> 0.19222993
A17: Depriciation % Sales | B17: =IFERROR('Historical FS'!B23,0) -> 0.038689076 | C17: =IFERROR('Historical FS'!C23,0) -> 0.034192176 | D17: =IFERROR('Historical FS'!D23,0) -> 0.029725644 | E17: =IFERROR('Historical FS'!E23,0) -> 0.029925862 | F17: =IFERROR('Historical FS'!F23,0) -> 0.027743758 | G17: =IFERROR('Historical FS'!G23,0) -> 0.026526754 | H17: =IFERROR('Historical FS'!H23,0) -> 0.023851036 | I17: =IFERROR('Historical FS'!I23,0) -> 0.022425142 | ... K17: =IFERROR('Historical FS'!K23,0) -> 0.026726649 | M17: =IFERROR(AVERAGE(B17:K17),0) -> 0.028308037 | N17: =IFERROR(MEDIAN(B17:K17),0) -> 0.027235203
A18: Operating Income % Sales | B18: =IFERROR('Ratio Analysis'!B12,0) -> 0.16367075 | C18: =IFERROR('Ratio Analysis'!C12,0) -> 0.17525975 | D18: =IFERROR('Ratio Analysis'!D12,0) -> 0.20208337 | E18: =IFERROR('Ratio Analysis'!E12,0) -> 0.20662549 | F18: =IFERROR('Ratio Analysis'!F12,0) -> 0.21206844 | G18: =IFERROR('Ratio Analysis'!G12,0) -> 0.21514607 | H18: =IFERROR('Ratio Analysis'!H12,0) -> 0.19549552 | I18: =IFERROR('Ratio Analysis'!I12,0) -> 0.21133622 | ... K18: =IFERROR('Ratio Analysis'!K12,0) -> 0.20945957 | M18: =IFERROR(AVERAGE(B18:K18),0) -> 0.2007403 | N18: =IFERROR(MEDIAN(B18:K18),0) -> 0.20804253
A20: Return on Capital Employed | B20: =IFERROR(('Historical FS'!B16-'Historical FS'!B22)/('Historical FS'!B45+'Historical FS'!B46+ 'Historical FS'!B47),0) -> 0.45126799 | C20: =IFERROR(('Historical FS'!C16-'Historical FS'!C22)/('Historical FS'!C45+'Historical FS'!C46+ 'Historical FS'!C47),0) -> 0.50764383 | D20: =IFERROR(('Historical FS'!D16-'Historical FS'!D22)/('Historical FS'!D45+'Historical FS'!D46+ 'Historical FS'!D47),0) -> 0.61527469 | E20: =IFERROR(('Historical FS'!E16-'Historical FS'!E22)/('Historical FS'!E45+'Historical FS'!E46+ 'Historical FS'!E47),0) -> 1.2125049 | F20: =IFERROR(('Historical FS'!F16-'Historical FS'!F22)/('Historical FS'!F45+'Historical FS'!F46+ 'Historical FS'!F47),0) -> 1.3065723 | G20: =IFERROR(('Historical FS'!G16-'Historical FS'!G22)/('Historical FS'!G45+'Historical FS'!G46+ 'Historical FS'!G47),0) -> 1.4331719 | H20: =IFERROR(('Historical FS'!H16-'Historical FS'!H22)/('Historical FS'!H45+'Historical FS'!H46+ 'Historical FS'!H47),0) -> 1.2101301 | I20: =IFERROR(('Historical FS'!I16-'Historical FS'!I22)/('Historical FS'!I45+'Historical FS'!I46+ 'Historical FS'!I47),0) -> 1.4807835 | ... K20: =IFERROR(('Historical FS'!K16-'Historical FS'!K22)/('Historical FS'!K45+'Historical FS'!K46+ 'Historical FS'!K47),0) -> 0.80079674 | M20: =IFERROR(AVERAGE(B20:K20),0) -> 1.0449562 | N20: =IFERROR(MEDIAN(B20:K20),0) -> 1.2113175
A21: Retained Earning % | B21: =IFERROR('Historical FS'!B41,0) -> 0.39337501 | C21: =IFERROR('Historical FS'!C41,0) -> 0.32319885 | D21: =IFERROR('Historical FS'!D41,0) -> 0.30996994 | E21: =IFERROR('Historical FS'!E41,0) -> -0.67521489 | F21: =IFERROR('Historical FS'!F41,0) -> 0.073966472 | G21: =IFERROR('Historical FS'!G41,0) -> 0.089694629 | H21: =IFERROR('Historical FS'!H41,0) -> 0.11264495 | I21: =IFERROR('Historical FS'!I41,0) -> 0.4405153 | ... K21: =IFERROR('Historical FS'!K41,0) -> 0.21456027 | M21: =IFERROR(AVERAGE(B21:K21),0) -> 0.14932759 | N21: =IFERROR(MEDIAN(B21:K21),0) -> 0.21256283
A22: Return on Equity % | B22: =IFERROR('Historical FS'!B31/SUM('Historical FS'!B45:B46),0) -> 0.30507597 | C22: =IFERROR('Historical FS'!C31/SUM('Historical FS'!C45:C46),0) -> 0.3581809 | D22: =IFERROR('Historical FS'!D31/SUM('Historical FS'!D45:D46),0) -> 0.43740983 | E22: =IFERROR('Historical FS'!E31/SUM('Historical FS'!E45:E46),0) -> 1.0258329 | F22: =IFERROR('Historical FS'!F31/SUM('Historical FS'!F45:F46),0) -> 1.0312429 | G22: =IFERROR('Historical FS'!G31/SUM('Historical FS'!G45:G46),0) -> 1.0883846 | H22: =IFERROR('Historical FS'!H31/SUM('Historical FS'!H45:H46),0) -> 0.97208408 | I22: =IFERROR('Historical FS'!I31/SUM('Historical FS'!I45:I46),0) -> 1.219383 | ... K22: =IFERROR('Historical FS'!K31/SUM('Historical FS'!K45:K46),0) -> 0.80504718 | M22: =IFERROR(AVERAGE(B22:K22),0) -> 0.84198246 | N22: =IFERROR(MEDIAN(B22:K22),0) -> 0.99895849
A23: Self Sustained Growth Rate | B23: =IFERROR(B21*B22,0) -> 0.12000926 | C23: =IFERROR(C21*C22,0) -> 0.11576365 | D23: =IFERROR(D21*D22,0) -> 0.1355839 | E23: =IFERROR(E21*E22,0) -> -0.69265766 | F23: =IFERROR(F21*F22,0) -> 0.076277398 | G23: =IFERROR(G21*G22,0) -> 0.097622253 | H23: =IFERROR(H21*H22,0) -> 0.10950036 | I23: =IFERROR(I21*I22,0) -> 0.53715685 | ... K23: =IFERROR(K21*K22,0) -> 0.17273114 | M23: =IFERROR(AVERAGE(B23:K23),0) -> 0.091986122 | N23: =IFERROR(MEDIAN(B23:K23),0) -> 0.11788646
A24: Interest Coverage Ratio | B24: =IFERROR(('Historical FS'!B16-'Historical FS'!B22)/'Historical FS'!B19,0) -> 16.457705 | C24: =IFERROR(('Historical FS'!C16-'Historical FS'!C22)/'Historical FS'!C19,0) -> 19.08901 | D24: =IFERROR(('Historical FS'!D16-'Historical FS'!D22)/'Historical FS'!D19,0) -> 20.383921 | E24: =IFERROR(('Historical FS'!E16-'Historical FS'!E22)/'Historical FS'!E19,0) -> 19.793448 | F24: =IFERROR(('Historical FS'!F16-'Historical FS'!F22)/'Historical FS'!F19,0) -> 17.244 | G24: =IFERROR(('Historical FS'!G16-'Historical FS'!G22)/'Historical FS'!G19,0) -> 15.724812 | H24: =IFERROR(('Historical FS'!H16-'Historical FS'!H22)/'Historical FS'!H19,0) -> 21.370771 | I24: =IFERROR(('Historical FS'!I16-'Historical FS'!I22)/'Historical FS'!I19,0) -> 33.884483 | ... K24: =IFERROR(('Historical FS'!K16-'Historical FS'!K22)/'Historical FS'!K19,0) -> 31.113309 | M24: =IFERROR(AVERAGE(B24:K24),0) -> 23.132079 | N24: =IFERROR(MEDIAN(B24:K24),0) -> 20.088685
A26: Debtor Turnover Ratio | B26: =IFERROR('Historical FS'!B4/'Historical FS'!B57,0) -> 93.345655 | C26: =IFERROR('Historical FS'!C4/'Historical FS'!C57,0) -> 112.50534 | D26: =IFERROR('Historical FS'!D4/'Historical FS'!D57,0) -> 90.635444 | E26: =IFERROR('Historical FS'!E4/'Historical FS'!E57,0) -> 99.484437 | F26: =IFERROR('Historical FS'!F4/'Historical FS'!F57,0) -> 80.943612 | G26: =IFERROR('Historical FS'!G4/'Historical FS'!G57,0) -> 88.814786 | H26: =IFERROR('Historical FS'!H4/'Historical FS'!H57,0) -> 88.055448 | I26: =IFERROR('Historical FS'!I4/'Historical FS'!I57,0) -> 99.67325 | ... K26: =IFERROR('Historical FS'!K4/'Historical FS'!K57,0) -> 55.628693 | M26: =IFERROR(AVERAGE(B26:K26),0) -> 89.027514 | N26: =IFERROR(MEDIAN(B26:K26),0) -> 89.725115
